Workbook

Sheet 1_FAVT_1_Ori
A1: Câmara Municipal da Praia
A3: REQUERENTE: | C3: Data:
A4: xxx | C4: =TODAY() -> 44945 | H4: Alta | I4: 603 | J4: Praia Nordeste | K4: Achada Bela Costa Pila Cana | M4: Habitação Unifamiliar
B5: Nº Processo | C5: Elaborado por: | H5: Média | I5: 702 | J5: Praia Noroeste | K5: Achada Bombena | M5: Habitação Multifamiliar
B6: 20xxxx | C6: xxx | H6: Baixa | I6: 505 | J6: Praia Ocidental | K6: Achada Eugenio Lima | M6: Terciário Pequeno comércio
B7: Referência Cadastral | C7: Versão: FAVT V4.1 (2020-07) | I7: 401 | J7: Pria Oriental | K7: Achada Grande Frente | M7: Terciario Grossista
A8: [SUB-BAIRRO]-[QUARTEIRÃO]-[LOTE] : | B8: 0-0-0 | C8: PDM (BO 68/2016 de 7/12); Revisão Geral | I8: 404 | J8: Pria Oriental | K8: Achada Grande Tras | M8: Terciário Serviços
C9: =IF('4_AV e MU'!J13=0,"(FAVT-MU)","") | I9: 709 | J9: Praia Noroeste | K9: Achada Laranjo | M9: Misto (Habitação + Terciário/Com-Serv)
I10: 107 | J10: Praia Norte | K10: Achada Limpo | M10: Estacionamento
A11: LOCALIZAÇÃO DO TERRENO (BAIRRO/LOCALIDADE): | C11: Palmarejo | I11: 105 | J11: Praia Norte | K11: Achada Mato | M11: Industria poluente
A12: Parametro Valorização do Bairro: | B12: =VLOOKUP($C$18,'PREÇO BAIRROS'!$A$5:$D$92,4,0) -> II | C12: Alta | I12: 409 | J12: Pria Oriental | K12: Achada Palha de Se | M12: Industria não poluente
A13: Referência/Nº de Matriz (Código da Matriz): | B13: R/U_xxx-y | C13: OBS: | I13: 408 | J13: Pria Oriental | K13: Achada Ribeirão Pedro | M13: Equipamento
A14: (ex: R_123-0) | B14: "[R/U]_[Número]-[Fracção]" | I14: 301 | J14: Praia Sul | K14: Achada S. Antonio | M14: Turismo
I15: 117 | J15: Praia Norte | K15: Achada S. Filipe | M15: Recreio Urbano (inclui Áreas Verdes)
A16: DESCRIÇÃO DO APROVEITAMENTO URBANÍSTICO (FORMAÇÃO DE PREÇO TERRENO #1) | I16: 706 | J16: Praia Noroeste | K16: Achada S. Jorginho | M16: Recreio Rural
I17: 504 | J17: Praia Ocidental | K17: Achadinha | M17: Infra-estruturas (técnicas e públicas)
A18: Código do Bairro (Zonas Urbanas: 0100-Praia Norte; 0200-Praia Centro; 0300-Praia Sul; 0400-Praia Oriental; 0500-Praia Ocidental; Zonas Periurbanas/Rurais: 0600-Praia Nordeste; 0700-Praia Noroeste; 0800-Praia Sudoeste) | C18: =IF(C11="","",VLOOKUP($C$11,'PREÇO BAIRROS'!$C$5:$H$92,6,0)) -> 0307 | I18: 103 | J18: Praia Norte | K18: Achadinha Pires | M18: Agrícola
A19: Área Total (A) | C19: 250 | I19: 607 | J19: Praia Nordeste | K19: Agostinho Alves | M19: Florestal
A20: Área Coberta (B) | C20: 220 | I20: 106 | J20: Praia Norte | K20: Agua Funda | M20: Extração mineira
A21: Área Descoberta (A-B) | C21: =C19-C20 -> 30 | I21: 503 | J21: Praia Ocidental | K21: Bairro Craveiro Lopes | M21: Pesca
A22: Índice de Ocupação (io) do Solo (B/A) | C22: =C20/C19 -> 0.88 | E22: 1 | I22: 508 | J22: Praia Ocidental | K22: Bela Vista
A23: Nº de Visas (1 a 4) | C23: 1 | E23: 2 | I23: 705 | J23: Praia Noroeste | K23: Bom Coi Norte
A24: Nº de Piso (aproveitamento urbanístico) | C24: 5 | E24: 3 | I24: 514 | J24: Praia Ocidental | K24: Bom Coi Sul
A25: Largura do lote/ponderação Infra-estruturas (min. 10 m) | C25: 25 | E25: 4 | I25: 802 | J25: Praia Sudoeste | K25: Caiada
A26: Largura da fachada/ponderação Proporção (min. 10 m) | C26: 10 | I26: 112 | J26: Praia Norte | K26: Calabaceira
A27: Uso | C27: Misto (Habitação + Terciário/Com-Serv) | I27: 713 | J27: Praia Noroeste | K27: Cambudjane
A28: Zona Histórica? | C28: =VLOOKUP(C18,'PREÇO BAIRROS'!$A$5:$I$92,9,0) -> Não | I28: 302 | J28: Praia Sul | K28: Chã de Areia Encosta ASA
A29: Edifício com valor histórico (Deliberação nº35/2012) | C29: Não | D29: (sem ponderação) | F29: Não | I29: 804 | J29: Praia Sudoeste | K29: Chã de Poeira
A30: F1: Ponderação nº de pisos | C30: =x_Cálculo!E18 -> 0.15 | D30: =+x_Cálculo!G18 -> 0.15 | F30: Sim | I30: 704 | J30: Praia Noroeste | K30: Chão de Limão
A31: F2: Ponderação elevador | C31: =x_Cálculo!E19 -> 0 | D31: =+x_Cálculo!G19 -> 0 | I31: 309 | J31: Praia Sul | K31: Cidadela Cova Minhoto
A32: F3: Ponderação proporção altura do edificado | C32: =x_Cálculo!E20 -> 0 | D32: =+x_Cálculo!G20 -> 0 | I32: 104 | J32: Praia Norte | K32: Coqueiro Castelão
A33: F4: Ponderação uso | C33: =x_Cálculo!E21 -> 0.1 | D33: =+x_Cálculo!G21 -> 0.1 | I33: 203 | J33: Praia Centro | K33: Fazenda Sucupira
A34: F5: Ponderação infra-estruturas | C34: =x_Cálculo!E22 -> 0.12 | D34: =+x_Cálculo!G22 -> 0.12 | I34: 205 | J34: Praia Centro | K34: Gamboa
A35: Total ponderação factores (F1xF2xF3xF4xF5) | C35: =x_Cálculo!E23 -> 1.4168 | I35: 511 | J35: Praia Ocidental | K35: Gato Valente Zona Enavi
C36: PREÇO (CVE) | I36: 115 | J36: Praia Norte | K36: Gonçalo Afonso
B37: Preço de referência do terreno em função da localização ($/m2) | C37: =x_Cálculo!C4 -> 6000 | I37: 206 | J37: Praia Centro | K37: Ilheu de Santa Maria
B38: Valor ponderado do Terreno F1 a F5 ($/m2) | C38: =x_Cálculo!E25 -> 8500.8 | I38: 608 | J38: Praia Nordeste | K38: Ilheu S. Filipe
B39: Ponderaçã índice de ocupação ($/m2) | C39: =x_Cálculo!E26 -> 480 | D39: =x_Cálculo!G26 -> 480 | I39: 712 | J39: Praia Noroeste | K39: Joao Bom (Djamban)
B40: Preço ponderado ($/m2) | C40: =x_Cálculo!E28 -> 8980.8 | D40: =+x_Cálculo!G28 -> 8980.8 | I40: 102 | J40: Praia Norte | K40: Lem Cachorro
B41: Preço total ponderado nº de vista ($/m2) | C41: =x_Cálculo!E29 -> 8980.8 | D41: =+x_Cálculo!G29 -> 8980.8
...

Sheet 2_FAVT_2_Alt
A1: Câmara Municipal da Praia
A3: REQUERENTE: | C3: Data: | H3: Alta | I3: Habitação Unifamiliar
A4: ='1_FAVT_1_Ori'!A4 -> xxx | C4: =TODAY() -> 44945 | H4: Média | I4: Habitação Multifamiliar
B5: Nº Processo | C5: Elaborado por: | H5: Baixa | I5: Terciário Pequeno comércio
B6: ='1_FAVT_1_Ori'!B6 -> 20xxxx | C6: xxx | I6: Terciario Grossista
B7: Referência Cadastral | C7: ='1_FAVT_1_Ori'!C7 -> Versão: FAVT V4.1 (2020-07) | I7: Terciário Serviços
A8: [SUB-BAIRRO]-[QUARTEIRÃO]-[LOTE] : | B8: =+'1_FAVT_1_Ori'!B8 -> 0-0-0 | C8: =+'1_FAVT_1_Ori'!C8 -> PDM (BO 68/2016 de 7/12); Revisão Geral | I8: Misto (Habitação + Terciário/Com-Serv)
C9: ='1_FAVT_1_Ori'!C9 | I9: Estacionamento
I10: Industria poluente
A11: LOCALIZAÇÃO DO TERRENO (BAIRRO/LOCALIDADE): | C11: =+'1_FAVT_1_Ori'!C11 -> Palmarejo | I11: Industria não poluente
A12: Parametro Valorização do Bairro: | B12: =VLOOKUP($C$18,'PREÇO BAIRROS'!$A$5:$D$92,4,0) -> II | C12: Alta | I12: Equipamento
A13: ='1_FAVT_1_Ori'!A13 -> Referência/Nº de Matriz (Código da Matriz): | B13: ='1_FAVT_1_Ori'!B13 -> R/U_xxx-y | C13: OBS: | G13: MU | I13: Turismo
A14: ='1_FAVT_1_Ori'!A14 -> (ex: R_123-0) | B14: ='1_FAVT_1_Ori'!B14 -> "[R/U]_[Número]-[Fracção]" | G14: =IF(C27<>'1_FAVT_1_Ori'!C27,0,"") | I14: Recreio Urbano (inclui Áreas Verdes)
I15: Recreio Rural
A16: DESCRIÇÃO DO APROVEITAMENTO URBANÍSTICO (FORMAÇÃO DE PREÇO TERRENO #2) | I16: Infra-estruturas (técnicas e públicas)
I17: Agrícola
A18: Código do Bairro (Zonas Urbanas: 0100-Praia Norte; 0200-Praia Centro; 0300-Praia Sul; 0400-Praia Oriental; 0500-Praia Ocidental; Zonas Periurbanas/Rurais: 0600-Praia Nordeste; 0700-Praia Noroeste; 0800-Praia Sudoeste) | C18: =IF(C11="","",VLOOKUP($C$11,'PREÇO BAIRROS'!$C$5:$H$92,6,0)) -> 0307 | I18: Florestal
A19: Área Total (A) | C19: 250 | I19: Extração mineira
A20: Área Coberta (B) | C20: 220 | I20: Pesca
A21: Área Descoberta (A-B) | C21: =C19-C20 -> 30
A22: Índice de Ocupação (io) do Solo (B/A) | C22: =C20/C19 -> 0.88 | E22: 1
A23: Nº de Visas (1 a 4) | C23: 1 | E23: 2
A24: Nº de Piso (aproveitamento urbanístico) | C24: 6 | E24: 3
A25: Largura do lote/ponderação Infra-estruturas (min. 10 m) | C25: 25 | E25: 4
A26: Largura da fachada/ponderação Proporção (min. 10 m) | C26: 10
A27: Uso | C27: Misto (Habitação + Terciário/Com-Serv)
A28: Zona Histórica? | C28: =VLOOKUP(C18,'PREÇO BAIRROS'!$A$5:$I$92,9,0) -> Não
A29: Edifício com valor histórico (Deliberação nº35/2012) | C29: Não | D29: (sem ponderação) | F29: Não
A30: F1: Ponderação nº de pisos | C30: =y_Cálculo!E18 -> 0.2 | D30: =+y_Cálculo!G18 -> 0.2 | F30: Sim
A31: F2: Ponderação elevador | C31: =y_Cálculo!E19 -> 0.14166667 | D31: =+y_Cálculo!G19 -> 0.14166667
A32: F3: Ponderação proporção altura do edificado | C32: =y_Cálculo!E20 -> 1.1 | D32: =+y_Cálculo!G20 -> 1.1
A33: F4: Ponderação uso | C33: =y_Cálculo!E21 -> 0.1 | D33: =+y_Cálculo!G21 -> 0.1
A34: F5: Ponderação infra-estruturas | C34: =y_Cálculo!E22 -> 0.12 | D34: =+y_Cálculo!G22 -> 0.12
A35: Total ponderação factores (F1xF2xF3xF4xF5) | C35: =y_Cálculo!E23 -> 3.544464
C36: PREÇO (CVE)
B37: Preço de referência do terreno em função da localização ($/m2) | C37: =+y_Cálculo!C4 -> 6000
B38: Valor ponderado do Terreno F1 a F5 ($/m2) | C38: =+y_Cálculo!E25 -> 21266.784
B39: Ponderaçã índice de ocupação ($/m2) | C39: =y_Cálculo!E26 -> 480 | D39: =y_Cálculo!G26 -> 480
B40: Preço ponderado ($/m2) | C40: =y_Cálculo!E28 -> 21746.784 | D40: =y_Cálculo!G28 -> 21746.784
B41: Preço total ponderado nº de vista ($/m2) | C41: =y_Cálculo!E29 -> 21746.784 | D41: =y_Cálculo!G29 -> 21746.784
...

Sheet RESUMO
A1: Câmara Municipal da Praia
A3: REQUERENTE: | H3: Data:
A4: =+'1_FAVT_1_Ori'!A4 -> xxx | H4: =TODAY() -> 44945
G5: Nº Processo | H5: =+'1_FAVT_1_Ori'!C7 -> Versão: FAVT V4.1 (2020-07)
G6: =+'1_FAVT_1_Ori'!B6 -> 20xxxx | H6: ='1_FAVT_1_Ori'!C8 -> PDM (BO 68/2016 de 7/12); Revisão Geral
H7: =+'1_FAVT_1_Ori'!C9
A9: 1 | B9: X | C9: FAVT 1 | E9: =IF(B9="x",'1_FAVT_1_Ori'!C42,"") -> 2245200
D10: IUP e Custas de Terreno | E10: =IF(E9="","",'1_FAVT_1_Ori'!B47) -> 73730
A12: 2 | B12: X | C12: FAVT 2 | E12: =IF(B12="x",'2_FAVT_2_Alt'!C42,"") -> 5436696
D13: IUP e Custas de Terreno | E13: =IF(E12="","",'2_FAVT_2_Alt'!B47) -> 153517.4
A15: 3 | B15: X | C15: Valor Ampliação Horizontal/Vertical/Outras | E15: =IF(B15="x",'3_AHV e MU'!D11,"") -> 3191496
D16: IUP e Custas de Terreno | E16: =IF(E15="","",'3_AHV e MU'!D24) -> 49515 | G16: Área #1 | H16: ='1_FAVT_1_Ori'!C19 -> 250 | I16: (m2)
G17: Área #2 | H17: ='2_FAVT_2_Alt'!C19 -> 250
A18: 3.1 | B18: X | C18: Valor Mudança de Uso (MU): | E18: =IF(B18="x",'3_AHV e MU'!E16,"") -> 0 | G18: Diferença Área | H18: =H17-H16 -> 0
G19: Uso #1 | H19: ='1_FAVT_1_Ori'!C27 -> Misto (Habitação + Terciário/Com-Serv) | I19: =VLOOKUP(H19,Factor4_Uso!$AB$6:$AD$23,3,0) -> M
A20: 3.2 | B20: X | C20: Cálculo Valor Ampliação Horizontal* | E20: =IF(B20="x",'3a_AH'!E18,"") -> 0 | G20: Uso #2 | H20: ='2_FAVT_2_Alt'!C27 -> Misto (Habitação + Terciário/Com-Serv) | I20: =VLOOKUP(H20,Factor4_Uso!$AB$6:$AD$23,3,0) -> M
D21: IUP e Custas de Terreno | E21: =IF(E20="","",'3a_AH'!D24) | G21: nº Piso #1 | H21: ='1_FAVT_1_Ori'!C24 -> 5
C22: (*: parâmetros urbanísticos base de referência) | G22: nº Piso #2 | H22: ='2_FAVT_2_Alt'!C24 -> 6
G23: Diferença Pisos | H23: =H22-H21 -> 1
A24: 4 | B24: X | C24: Valor Ampliação Vertical/Outras Alterações | E24: =IF(B24="x",'4_AV e MU'!D11,"") -> 3191496 | G24: Área Coberta #1 | H24: ='1_FAVT_1_Ori'!C19 -> 250
G25: Área Coberta #2 | H25: ='2_FAVT_2_Alt'!C19 -> 250
A26: 5 | B26: X | C26: Valor Ampliação Área Coberta | E26: =IF(B26="x",'5_ACob e AVer'!E8,"") -> 0 | G26: Diferencial | H26: =ABS(H25-H24) -> 0 | J26: ='1_FAVT_1_Ori'!C9
G27: Área Verde #1 | H27: ='1_FAVT_1_Ori'!C21 -> 30 | J27: ='1_FAVT_1_Ori'!C11 -> Palmarejo
A28: 5.1 | B28: X | C28: Valor Ampliação Área Verde/Descoberta | E28: =IF(B28="x",'5_ACob e AVer'!E17,"") -> 0 | G28: Área Verde #2 | H28: ='2_FAVT_2_Alt'!C21 -> 30 | J28: ='2_FAVT_2_Alt'!C11 -> Palmarejo
G29: Diferencial | H29: =ABS(H28-H27) -> 0
A30: 6 | B30: X | C30: Valor Déficit Estacionamento | E30: =+'6_Estaciona'!E8 -> 0 | G30: Défict Estacion. | H30: =+'6_Estaciona'!E14 -> 0
D34: TOTAL (CVE)
C37: Contrato Compra e Venda | D37: 15200
C38: Contrato Direito Superficie | D38: 24700
C39: Contrato Promessa Compra e Venda | D39: 11000
D42: =ABS(IF((D17-D16=0),+H17*0.05*'2_FAVT_2_Alt'!C37,D17-D16)) -> #VALUE!
B44: X

Sheet 3_AHV e MU
A1: Câmara Municipal da Praia
A3: REQUERENTE: | H3: Data:
A4: =+'1_FAVT_1_Ori'!A4 -> xxx | H4: =TODAY() -> 44945
G5: Nº Processo | H5: =+'1_FAVT_1_Ori'!C7 -> Versão: FAVT V4.1 (2020-07)
G6: =+'1_FAVT_1_Ori'!B6 -> 20xxxx | H6: ='1_FAVT_1_Ori'!C8 -> PDM (BO 68/2016 de 7/12); Revisão Geral
B7: =IF(H11<>0,"x","") | C7: Cálculo Valor Ampliação Horizontal (*)
B8: =IF(D11<>0,"x","") -> x | C8: Cálculo Valor Ampliação Vertical/Outras Alterações
C9: V1 | D9: =CEILING('1_FAVT_1_Ori'!C42,1) -> 2245200 | G9: Área #1 | H9: ='1_FAVT_1_Ori'!C19 -> 250 | I9: (m2)
C10: V2 | D10: =CEILING('2_FAVT_2_Alt'!C42,1) -> 5436696 | G10: Área #2 | H10: ='2_FAVT_2_Alt'!C19 -> 250
C11: Diferencial: | D11: =ABS(D10-D9) -> 3191496 | G11: Diferença Área | H11: =H10-H9 -> 0
C12: (*): inclui IUP e Custas de Terreno/Ampliação Horizontal | G12: Uso #1 | H12: ='1_FAVT_1_Ori'!C27 -> Misto (Habitação + Terciário/Com-Serv) | I12: =VLOOKUP(H12,Factor4_Uso!$AB$6:$AD$23,3,0) -> M
C13: pode incluir Ampliação Vertical e Mudança de Uso | G13: Uso #2 | H13: ='2_FAVT_2_Alt'!C27 -> Misto (Habitação + Terciário/Com-Serv) | I13: =VLOOKUP(H13,Factor4_Uso!$AB$6:$AD$23,3,0) -> M
C14: (cálculo geral/em simultâneo de ampliações e mudanças de uso) | G14: nº Piso #1 | H14: ='1_FAVT_1_Ori'!C24 -> 5
G15: nº Piso #2 | H15: ='2_FAVT_2_Alt'!C24 -> 6
B16: =IF(E16<>0,"x","") | C16: Valor Mudança de Uso (MU): | E16: ='4_AV e MU'!E17 -> 0 | G16: Diferença Pisos | H16: =H15-H14 -> 1
C18: VALOR CALCULADO: | E18: =CEILING(D11+E16,1) -> 3191496
C19: CONTAS: | G19: Ponderação MU | H19: =+'4_AV e MU'!E18 -> 0.1 | J19: ='1_FAVT_1_Ori'!C9
B20: Contrato Compra e Venda | D20: =IF(B20=C30,D30,IF(B20=C31,D31,IF(B20=C32,D32))) -> 15200 | G20: Bairro | H20: =+'4_AV e MU'!E19 -> Palmarejo | J20: ='1_FAVT_1_Ori'!C11 -> Palmarejo
C21: Certidão | D21: 2400 | G21: Preço ref. Bairro | H21: =+'4_AV e MU'!E20 -> 6000
C22: Imposto Selo | D22: =0.01*E18 -> 31914.96 | G22: Área | H22: =+'4_AV e MU'!E21 -> 220
C23: IUP (1,5%) | D23: =E16*0.015 -> 0
C24: CUSTAS DE TERRENO: | D24: =IF(E18=0,"",CEILING(SUM(D20:D23),1)) -> 49515
D27: TOTAL (CVE) | E27: =CEILING(D23+D24+E16,1) -> 49515
C30: Contrato Compra e Venda | D30: 15200
C31: Contrato Direito Superficie | D31: 24700
C32: Contrato Promessa Compra e Venda | D32: 11000
D35: =ABS(IF((D10-D9=0),+H10*0.05*'2_FAVT_2_Alt'!C37,D10-D9)) -> 3191496

Sheet 3a_AH
A1: Câmara Municipal da Praia
A3: REQUERENTE: | H3: Data:
A4: =+'1_FAVT_1_Ori'!A4 -> xxx | H4: =TODAY() -> 44945
G5: Nº Processo | H5: =+'1_FAVT_1_Ori'!C7 -> Versão: FAVT V4.1 (2020-07)
G6: =+'1_FAVT_1_Ori'!B6 -> 20xxxx | H6: ='1_FAVT_1_Ori'!C8 -> PDM (BO 68/2016 de 7/12); Revisão Geral
B8: =IF(E18<>0,"x","") | C8: Cálculo Valor Ampliação Horizontal (*)
C9: Bairro | D9: =+'4_AV e MU'!E19 -> Palmarejo | G9: Área #1 | H9: ='1_FAVT_1_Ori'!C19 -> 250 | I9: (m2)
C10: Ponderação | E10: A | G10: Área #2 | H10: ='2_FAVT_2_Alt'!C19 -> 250
C11: Preço ref. Bairro | E11: =IF(E10=J12,z_Cálculo!C4,IF(E10=J13,z_Cálculo!C5,IF(E10=J14,z_Cálculo!C6))) -> 6000 | G11: Diferença Área | H11: =H10-H9 -> 0
C12: Área | E12: =IF(E13="",H11,E13) -> 0 | J12: A
C13: Área de cálculo | J13: B
J14: C
C15: (*): inclui IUP e Custas de Terreno/Ampliação Horizontal
C16: (parâmetros urbanísticos de referência)
C18: VALOR CALCULADO: | E18: =CEILING(E11*E12,1) -> 0
C19: CONTAS: | J19: ='1_FAVT_1_Ori'!C9
B20: Contrato Compra e Venda | D20: =IF(B20=C30,D30,IF(B20=C31,D31,IF(B20=C32,D32))) -> 15200 | J20: ='1_FAVT_1_Ori'!C11 -> Palmarejo
C21: Certidão | D21: 2400
C22: Imposto Selo | D22: =0.01*E18 -> 0
C23: IUP (1,5%) | D23: =E16*0.015 -> 0
C24: CUSTAS DE TERRENO: | D24: =IF(E18=0,"",CEILING(SUM(D20:D23),1))
D27: TOTAL (CVE) | E27: =IF(E18=0,"",CEILING(D23+D24+E16,1))
C30: Contrato Compra e Venda | D30: 15200
C31: Contrato Direito Superficie | D31: 24700
C32: Contrato Promessa Compra e Venda | D32: 11000

Sheet 4_AV e MU
A1: Câmara Municipal da Praia
A3: REQUERENTE: | H3: Data:
A4: =+'1_FAVT_1_Ori'!A4 -> xxx | H4: =TODAY() -> 44945
G5: Nº Processo | H5: =+'1_FAVT_1_Ori'!C7 -> Versão: FAVT V4.1 (2020-07)
G6: =+'1_FAVT_1_Ori'!B6 -> 20xxxx | H6: ='1_FAVT_1_Ori'!C8 -> PDM (BO 68/2016 de 7/12); Revisão Geral
B8: =IF(D11<>0,"x","") -> x | C8: Cálculo Ampliação Vertical/Outras Alterações (*)
C9: V1 | D9: =CEILING('1_FAVT_1_Ori'!C42,1) -> 2245200 | G9: Área #1 | H9: ='1_FAVT_1_Ori'!C19 -> 250 | I9: (m2)
C10: V2 | D10: =CEILING('2_FAVT_2_Alt'!C42,1) -> 5436696 | G10: Área #2 | H10: ='2_FAVT_2_Alt'!C19 -> 250
C11: Diferencial: | D11: =ABS(CEILING(D10-D9,1)) -> 3191496 | G11: Diferença Área | H11: =+H10-H9 -> 0
C12: (*): não inclui IUP e Custas de Terreno/Ampliação Horizontal | G12: Uso #1 | H12: ='1_FAVT_1_Ori'!C27 -> Misto (Habitação + Terciário/Com-Serv) | I12: =VLOOKUP(H12,Factor4_Uso!$AB$6:$AD$23,3,0) -> M
G13: Uso #2 | H13: ='2_FAVT_2_Alt'!C27 -> Misto (Habitação + Terciário/Com-Serv) | I13: =VLOOKUP(H13,Factor4_Uso!$AB$6:$AD$23,3,0) -> M | J13: =IF(I12<>I13,0,"")
G14: nº Piso #1 | H14: ='1_FAVT_1_Ori'!C24 -> 5
G15: nº Piso #2 | H15: ='2_FAVT_2_Alt'!C24 -> 6
G16: Diferença Pisos | H16: =H15-H14 -> 1
B17: =IF(E17<>0,"x","") | C17: Cálculo Valor Mudança de Uso (MU): | E17: =IF(I12=I13,0,CEILING(E21*E20*E18,1)) -> 0
C18: Ponderação Uso/Mudança | E18: =VLOOKUP($I$12,Factor4_Uso!$E$6:$X$23,MATCH($I$13,Factor4_Uso!$E$5:$X$5,0),0) -> 0.1 | G18: Área Coberta #1 | H18: ='1_FAVT_1_Ori'!C20 -> 220 | J18: ='1_FAVT_1_Ori'!C9
C19: Bairro | E19: ='2_FAVT_2_Alt'!C11 -> Palmarejo | G19: Área Coberta #2 | H19: ='2_FAVT_2_Alt'!C20 -> 220 | J19: =+'1_FAVT_1_Ori'!C11 -> Palmarejo
C20: Preço ref. Bairro | E20: =+'2_FAVT_2_Alt'!C37 -> 6000 | G20: Diferencial | H20: =ABS(H19-H18) -> 0
C21: Área | E21: =+H19 -> 220
C22: Área de cálculo
D27: TOTAL (CVE) | E27: =CEILING(E17+D11,1) -> 3191496

Sheet 5_ACob e AVer
A1: Câmara Municipal da Praia
A3: REQUERENTE: | H3: Data:
A4: =+'1_FAVT_1_Ori'!A4 -> xxx | H4: =TODAY() -> 44945
G5: Nº Processo | H5: =+'1_FAVT_1_Ori'!C7 -> Versão: FAVT V4.1 (2020-07)
G6: =+'1_FAVT_1_Ori'!B6 -> 20xxxx | H6: ='1_FAVT_1_Ori'!C8 -> PDM (BO 68/2016 de 7/12); Revisão Geral
B8: =IF(E8<>0,"x","") | C8: Cálculo Ampliação Área Coberta (*) | E8: =CEILING(E11*E12,1) -> 0
C9: Bairro | D9: =+'1_FAVT_1_Ori'!C11 -> Palmarejo | G9: Área Coberta #1 | H9: ='1_FAVT_1_Ori'!C20 -> 220
C10: Ponderação Área Coberta | E10: B | G10: Área Coberta #2 | H10: ='2_FAVT_2_Alt'!C20 -> 220
C11: Preço ref. Área Coberta | E11: =IF(E10=J12,z_Cálculo!C4,IF(E10=J13,z_Cálculo!C5,IF(E10=J14,z_Cálculo!C6))) -> 4500 | G11: Diferencial | H11: =ABS(H10-H9) -> 0 | J11: =+H10-H9 -> 0
C12: Área | E12: =IF(E13="",H11,E13) -> 0 | J12: A
C13: Área de cálculo | J13: B
G14: Área Verde #1 | H14: ='1_FAVT_1_Ori'!C21 -> 30 | J14: C
G15: Área Verde #2 | H15: ='2_FAVT_2_Alt'!C21 -> 30
G16: Diferencial | H16: =ABS(H15-H14) -> 0
B17: =IF(E17<>0,"x","") | C17: Cálculo Ampliação Área Verde/Descoberta(*) | E17: =CEILING(E20*E21,1) -> 0
C18: Bairro | D18: =+D9 -> Palmarejo
C19: Ponderação Área Verde | E19: C
C20: Preço ref. Área Coberta | E20: =IF(E19=J12,z_Cálculo!C4,IF(E19=J13,z_Cálculo!C5,IF(E19=J14,z_Cálculo!C6))) -> 4500
C21: Área | E21: =IF(E22="",H16,E22) -> 0
C22: Área de cálculo
C25: (*): não inclui IUP e Custas de Terreno
D27: TOTAL (CVE) | E27: =CEILING(E17+E8,1) -> 0

Sheet 6_Estaciona
A1: Câmara Municipal da Praia
A3: REQUERENTE: | H3: Data:
A4: =+'1_FAVT_1_Ori'!A4 -> xxx | H4: =TODAY() -> 44945
G5: Nº Processo | H5: =+'1_FAVT_1_Ori'!C7 -> Versão: FAVT V4.1 (2020-07)
G6: =+'1_FAVT_1_Ori'!B6 -> 20xxxx | H6: ='1_FAVT_1_Ori'!C8 -> PDM (BO 68/2016 de 7/12); Revisão Geral
B8: =IF(E8<>0,"x","") | C8: Cálculo Déficit Estacionamento (*) | E8: =+E11*E14*E15 -> 0
C9: Bairro | D9: =+'1_FAVT_1_Ori'!C11 -> Palmarejo
C10: Ponderação Estacionamento | E10: B
C11: Preço ref. | E11: =IF(E10=J12,z_Cálculo!C4,IF(E10=J13,z_Cálculo!C5,IF(E10=J14,z_Cálculo!C6))) -> 4500 | J11: =+H10-H9 -> 0
C12: Nº Estacionamento Necessário | E12: 1 | J12: A
C13: Nº Estacionamento Projecto | E13: 1 | J13: B
C14: Déficit do nº Estacionamento | E14: =IF((E12-E13<=0),0,E12-E13) -> 0 | J14: C
C15: Área ref Estacionamento (2,5 x 5 m2) | E15: =2.5*5 -> 12.5
C18: (*) Artigo 27º do PDM da Praia (BO 68/2016 de 7 de Dezembro)
D27: TOTAL (CVE) | E27: =CEILING(E8,1) -> 0

Sheet x_Cálculo
B1: ZONA | C1: Bairro | D1: Cod. Bairro | E1: Zona Histórica
B2: =VLOOKUP($D$2,'PREÇO BAIRROS'!$A$5:$B$92,2,0) -> Praia Sul | C2: =+'1_FAVT_1_Ori'!C11 -> Palmarejo | D2: =+'1_FAVT_1_Ori'!C18 -> 0307 | E2: =+'1_FAVT_1_Ori'!C28 -> Não
B3: Preço ($/m2) | C3: Valorização Bairro/Ponderação | D3: =+'1_FAVT_1_Ori'!B12 -> II | E3: =IF(OR(AND(E2="Sim",E14>5),AND(E2="Não",E14>2)),"Proporcional","Não Proporcional") -> Não Proporcional
C4: =VLOOKUP($D$2,'PREÇO BAIRROS'!$A$5:$G$92,MATCH($D$4,'PREÇO BAIRROS'!$A$4:$G$4,0)) -> 6000 | D4: =+'1_FAVT_1_Ori'!C12 -> Alta | E4: Edificio Histórico
B5: Uso | C5: ='1_FAVT_1_Ori'!C27 -> Misto (Habitação + Terciário/Com-Serv) | D5: =VLOOKUP($C$5,Factor4_Uso!$AB$6:$AD$23,3,0) -> M | E5: ='1_FAVT_1_Ori'!C29 -> Não | F5: Sim
B6: Teste mudança de uso | C6: (sem alteração) | D6: =VLOOKUP($C$5,Factor4_Uso!$AB$6:$AD$23,3,0) -> M | F6: Não
B7: ÁREA TOTAL LOTE | E7: ='1_FAVT_1_Ori'!C19 -> 250
B8: ÁREA COBERTA TOTAL | C8: Índice de Ocupação (IO) = | D8: =E8/E7 -> 0.88 | E8: ='1_FAVT_1_Ori'!C20 -> 220 | F8: =(E7-E8)*C4 -> 180000
B9: ÁREA DESCOBERTA TOTAL | E9: =+E7-E8 -> 30 | F9: =E9*C4 -> 180000
B10: LARGURA TOTAL (FRENTE DO LOTE)/INFRA-ESTRUTURAS | E10: ='1_FAVT_1_Ori'!C25 -> 25
B11: LARGURA TOTAL FACHADA (EDIFÍCIO)/PROPORÇÃO | E11: ='1_FAVT_1_Ori'!C26 -> 10 | F11: =20*C4 -> 120000
B12: nº piso plano ou 2 (r/ch +1) [caso não haja plano] | E12: 20
B13: Nº PISOS TOTAL | E13: ='1_FAVT_1_Ori'!C24 -> 5 | F13: =+E11/E13 -> 2
B14: MCB/Piso - Correspondente a : | E14: =$E$11/$E$13 -> 2 | F14: =+F13*2 -> 4
B15: Num_Vista | E15: =+'1_FAVT_1_Ori'!C23 -> 1
B16: H MÁX. TOTAL | E16: =+E13*3 -> 15 | F16: Matriz Decisão
F17: Apreciação/ponderação | G17: (sem ponderação)
B18: F1: Ponderação altura/nº de pisos | E18: =IF(F18="",IF($E$13>1,VLOOKUP($E$13,Factor1_H!$A$11:$E$145,5,0),0),F18) -> 0.15 | G18: =IF($E$13>1,VLOOKUP($E$13,Factor1_H!$A$11:$E$145,5,0),0) -> 0.15
B19: F2: Ponderação elevador | E19: =IF(F19="",IF(E13>1,VLOOKUP($E$13,Factor2_Elev!$A$11:$D$154,4,0),0),F19) -> 0 | G19: =IF(E13>1,VLOOKUP($E$13,Factor2_Elev!$A$11:$D$154,4,0),0) -> 0
B20: F3: Ponderação proporção alçados (rectângulo de ouro) | E20: =IF(F20="",IF(OR(AND(E2="Sim",$E$14<5)),VLOOKUP($E$13,Factor3_proporção!$E$30:$G$1069,3,0),AND(E2="Não",$E$14<2)+VLOOKUP($E$13,Factor3_proporção!$K$30:$M$1016,3,0)),F20) -> 0 | G20: =IF(OR(AND(E2="Sim",$E$14<5)),VLOOKUP($E$13,Factor3_proporção!$E$30:$G$1069,3,0),AND(E2="Não",$E$14<2)+VLOOKUP($E$13,Factor3_proporção!$K$30:$M$1016,3,0)) -> 0
B21: F4: Ponderação uso | E21: =IF(F21="",VLOOKUP($D$5,Factor4_Uso!$E$6:$X$23,MATCH($D$6,Factor4_Uso!$E$5:$X$5,0),0),F21) -> 0.1 | F21: =IF('1_FAVT_1_Ori'!C9="(FAVT-MU)",'4_AV e MU'!J13,"") | G21: =+VLOOKUP($D$5,Factor4_Uso!$E$6:$X$23,MATCH($D$6,Factor4_Uso!$E$5:$X$5,0),0) -> 0.1
B22: F5: Ponderação infra-estruturas | E22: =IF(F22="",IF(E10<10,0,VLOOKUP($E$10,Factor5_infra!$B$8:$C$548,2,0)),F22) -> 0.12 | G22: =IF(E10<10,0,VLOOKUP($E$10,Factor5_infra!$B$8:$C$548,2,0)) -> 0.12
D23: Total ponderação factores (F1xF2xF3xF4xF5) | E23: =+(1+E18)*(1+E19)*(1+E20)*(1+E21)*(1+E22) -> 1.4168
D25: Preço normal $/m2 (ponderado) | E25: =E23*C4 -> 8500.8
D26: Ponderaçã índice de ocupação $/m2 | E26: =IF(F26="",IF($E$7<=200,0,IF(AND($E$7>200,$E$7<1000,(($D$8-0.8)*$C$4)>0),(($D$8-0.8)*$C$4),IF(AND($E$7>1000,(($D$8-0.4)*$C$4)>0),(($D$8-0.4)*$C$4),0))),F26) -> 480 | G26: =+IF($E$7<=200,0,IF(AND($E$7>200,$E$7<1000,(($D$8-0.8)*$C$4)>0),(($D$8-0.8)*$C$4),IF(AND($E$7>1000,(($D$8-0.4)*$C$4)>0),(($D$8-0.4)*$C$4),0))) -> 480
D27: Ponderação nº de vistas | E27: =IF(F27="",VLOOKUP($E$15,N_Vistas!$B$3:$C$6,2,0),F27) -> 0 | G27: =VLOOKUP($E$15,N_Vistas!$B$3:$C$6,2,0) -> 0
D28: Preço total $/m2 | E28: =IF(F28="",E25+E26,F28) -> 8980.8 | G28: =+E25+E26 -> 8980.8
D29: Preço total,Ponderado Vista $/m2 | E29: =IF(F29="",(1+$E$27)*$E$28,F29) -> 8980.8 | G29: =+(1+$E$27)*$E$28 -> 8980.8
D30: Valor terreno($) | E30: =IF(F30="",$E$29*$E$7,F30) -> 2245200 | G30: =$E$29*$E$7 -> 2245200
F37: =8000000/8 -> 1000000
E39: =30000/30 -> 1000
E41: =0.005 -> 0.005
D42: Aluguer espaço/dia | E42: =F25*E41*E7 -> 0

Sheet y_Cálculo
B1: ZONA | C1: Bairro | D1: Cod. Bairro | E1: Zona Histórica
B2: =VLOOKUP($D$2,'PREÇO BAIRROS'!$A$5:$B$92,2,0) -> Praia Sul | C2: ='2_FAVT_2_Alt'!C11 -> Palmarejo | D2: =IF(C2="","",VLOOKUP($C$2,'PREÇO BAIRROS'!$C$5:$H$92,6,0)) -> 0307 | E2: =+'2_FAVT_2_Alt'!C28 -> Não
B3: Preço ($/m2) | C3: Valorização Bairro/Ponderação | D3: =+'1_FAVT_1_Ori'!B12 -> II | E3: =IF(OR(AND(E2="Sim",E14>5),AND(E2="Não",E14>2)),"Proporcional","Não Proporcional") -> Não Proporcional
C4: =VLOOKUP($D$2,'PREÇO BAIRROS'!$A$5:$G$92,MATCH($D$4,'PREÇO BAIRROS'!$A$4:$G$4,0)) -> 6000 | D4: =+'2_FAVT_2_Alt'!C12 -> Alta | E4: Edificio Histórico
B5: Uso | C5: ='2_FAVT_2_Alt'!C27 -> Misto (Habitação + Terciário/Com-Serv) | D5: =VLOOKUP($C$5,Factor4_Uso!$AB$6:$AD$23,3,0) -> M | E5: ='2_FAVT_2_Alt'!C29 -> Não | F5: Sim
B6: Teste mudança de uso | C6: (sem alteração) | D6: =VLOOKUP($C$5,Factor4_Uso!$AB$6:$AD$23,3,0) -> M | F6: Não
B7: ÁREA TOTAL LOTE | E7: ='2_FAVT_2_Alt'!C19 -> 250
B8: ÁREA COBERTA TOTAL | C8: Índice de Ocupação (IO) = | D8: =E8/E7 -> 0.88 | E8: ='2_FAVT_2_Alt'!C20 -> 220 | F8: =(E7-E8)*C4 -> 180000
B9: ÁREA DESCOBERTA TOTAL | E9: =+E7-E8 -> 30 | F9: =E9*C4 -> 180000
B10: LARGURA TOTAL (FRENTE DO LOTE)/INFRA-ESTRUTURAS | E10: ='2_FAVT_2_Alt'!C25 -> 25
B11: LARGURA TOTAL FACHADA (EDIFÍCIO)/PROPORÇÃO | E11: ='2_FAVT_2_Alt'!C26 -> 10 | F11: =20*C4 -> 120000
B12: nº piso plano ou 2 (r/ch +1) [caso não haja plano] | E12: 20
B13: Nº PISOS TOTAL | E13: =IF(AND('1_FAVT_1_Ori'!C24=1,'2_FAVT_2_Alt'!C24=2),3,'2_FAVT_2_Alt'!C24) -> 6 | F13: =+E11/E13 -> 1.6666667 | G13: =IF(AND('1_FAVT_1_Ori'!C24=1,'2_FAVT_2_Alt'!C24=2),3,'2_FAVT_2_Alt'!C24) -> 6
B14: MCB/Piso - Correspondente a : | E14: =$E$11/$E$13 -> 1.6666667 | F14: =+F13*2 -> 3.3333333
B15: Num_Vista | E15: =+'2_FAVT_2_Alt'!C23 -> 1
B16: H MÁX. TOTAL | E16: =+E13*3 -> 18 | F16: Matriz Decisão
F17: Apreciação/ponderação | G17: (sem ponderação)
B18: F1: Ponderação altura/nº de pisos | E18: =IF(F18="",IF($E$13>1,VLOOKUP($E$13,Factor1_H!$A$11:$E$145,5,0),0),F18) -> 0.2 | G18: =IF($E$13>1,VLOOKUP($E$13,Factor1_H!$A$11:$E$145,5,0),0) -> 0.2
B19: F2: Ponderação elevador | E19: =IF(F19="",IF(E13>1,VLOOKUP($E$13,Factor2_Elev!$A$11:$D$154,4,0),0),F19) -> 0.14166667 | G19: =IF(E13>1,VLOOKUP($E$13,Factor2_Elev!$A$11:$D$154,4,0),0) -> 0.14166667
B20: F3: Ponderação proporção alçados (rectângulo de ouro) | E20: =IF(F20="",IF(OR(AND(E2="Sim",$E$14<5)),VLOOKUP($E$13,Factor3_proporção!$E$30:$G$1069,3,0),AND(E2="Não",$E$14<2)+VLOOKUP($E$13,Factor3_proporção!$K$30:$M$1016,3,0)),F20) -> 1.1 | G20: =IF(OR(AND(E2="Sim",$E$14<5)),VLOOKUP($E$13,Factor3_proporção!$E$30:$G$1069,3,0),AND(E2="Não",$E$14<2)+VLOOKUP($E$13,Factor3_proporção!$K$30:$M$1016,3,0)) -> 1.1
B21: F4: Ponderação uso | E21: =IF(F21="",VLOOKUP($D$5,Factor4_Uso!$E$6:$X$23,MATCH($D$6,Factor4_Uso!E5:$X$5,0),0),F21) -> 0.1 | F21: =IF('2_FAVT_2_Alt'!C9="(FAVT-MU)",'4_AV e MU'!J13,"") | G21: =+VLOOKUP($D$5,Factor4_Uso!$E$6:$X$23,MATCH($D$6,Factor4_Uso!$E$5:$X$5,0),0) -> 0.1
B22: F5: Ponderação infra-estruturas | E22: =IF(F22="",IF(E10<10,0,VLOOKUP($E$10,Factor5_infra!$B$8:$C$548,2,0)),F22) -> 0.12 | G22: =IF(E10<10,0,VLOOKUP($E$10,Factor5_infra!$B$8:$C$548,2,0)) -> 0.12
D23: Total ponderação factores (F1xF2xF3xF4xF5) | E23: =+(1+E18)*(1+E19)*(1+E20)*(1+E21)*(1+E22) -> 3.544464
D25: Preço normal $/m2 (ponderado) | E25: =E23*C4 -> 21266.784
D26: Ponderaçã índice de ocupação $/m2 | E26: =IF(F26="",IF($E$7<=200,0,IF(AND($E$7>200,$E$7<1000,(($D$8-0.8)*$C$4)>0),(($D$8-0.8)*$C$4),IF(AND($E$7>1000,(($D$8-0.4)*$C$4)>0),(($D$8-0.4)*$C$4),0))),F26) -> 480 | G26: =+IF($E$7<=200,0,IF(AND($E$7>200,$E$7<1000,(($D$8-0.8)*$C$4)>0),(($D$8-0.8)*$C$4),IF(AND($E$7>1000,(($D$8-0.4)*$C$4)>0),(($D$8-0.4)*$C$4),0))) -> 480
D27: Ponderação nº de vistas | E27: =IF(F27="",VLOOKUP($E$15,N_Vistas!$B$3:$C$6,2,0),F27) -> 0 | G27: =VLOOKUP($E$15,N_Vistas!$B$3:$C$6,2,0) -> 0
D28: Preço total $/m2 | E28: =IF(F28="",E25+E26,F28) -> 21746.784 | G28: =+E25+E26 -> 21746.784
D29: Preço total,Ponderado Vista $/m2 | E29: =IF(F29="",(1+$E$27)*$E$28,F29) -> 21746.784 | G29: =+(1+$E$27)*$E$28 -> 21746.784
D30: Valor terreno($) | E30: =IF(F30="",$E$29*$E$7,F30) -> 5436696 | G30: =$E$29*$E$7 -> 5436696
F37: =8000000/8 -> 1000000
E39: =30000/30 -> 1000
E41: =0.005 -> 0.005
D42: Aluguer espaço/dia | E42: =F25*E41*E7 -> 0

Sheet z_Cálculo
B1: ZONA | C1: Bairro | D1: Cod. Bairro
B2: =VLOOKUP($D$2,'PREÇO BAIRROS'!$A$5:$B$92,2,0) -> Praia Sul | C2: =+'1_FAVT_1_Ori'!C11 -> Palmarejo | D2: =IF(C2="","",VLOOKUP($C$2,'PREÇO BAIRROS'!$C$5:$H$92,6,0)) -> 0307
B3: Preço ($/m2) | C3: Valorização Bairro/Ponderação | D3: =+'1_FAVT_1_Ori'!B12 -> II
C4: =VLOOKUP($D$2,'PREÇO BAIRROS'!$A$5:$G$92,MATCH($D$4,'PREÇO BAIRROS'!$A$4:$G$4,0)) -> 6000 | D4: Alta
C5: =VLOOKUP($D$2,'PREÇO BAIRROS'!$A$5:$G$92,MATCH($D$5,'PREÇO BAIRROS'!$A$4:$G$4,0)) -> 4500 | D5: Média
B6: Teste mudança de uso | C6: =VLOOKUP($D$2,'PREÇO BAIRROS'!$A$5:$G$92,MATCH($D$5,'PREÇO BAIRROS'!$A$4:$G$4,0)) -> 4500 | D6: Baixa
F12: =8000000/8 -> 1000000
E14: =30000/30 -> 1000
E16: =0.005 -> 0.005
D17: Aluguer espaço/dia

Sheet Factor1_H
C3: Factor 1
J4: m | K4: 0.05
J6: penalidade | K6: 0.2
A8: Hplano | B8: =+x_Cálculo!E12*3 -> 60
A9: FiMAX | B9: 0.15
A10: K | B10: h | C10: Andar | D10: COND | E10: Factor1
A11: 2 | B11: 6 | C11: 2 | D11: =AND(B11>=6,B11<=$B$8) -> TRUE | E11: =IF(D11,$K$4/3*(B11-$B$11),$K$4/3*($B$8-$B$11)+$K$6+$B$9*((B11-$B$8)/B11)) -> 0
A12: 3 | B12: =3*A12 -> 9 | C12: =+C11+1 -> 3 | D12: =AND(B12>6,B12<=$B$8) -> TRUE | E12: =IF(D12,$K$4/3*(B12-$B$11),$K$4/3*($B$8-$B$11)+$K$6+$B$9*((B12-$B$8)/B12)) -> 0.05
A13: 4 | B13: =3*A13 -> 12 | C13: =+C12+1 -> 4 | D13: =AND(B13>6,B13<=$B$8) -> TRUE | E13: =IF(D13,$K$4/3*(B13-$B$11),$K$4/3*($B$8-$B$11)+$K$6+$B$9*((B13-$B$8)/B13)) -> 0.1
A14: 5 | B14: =3*A14 -> 15 | C14: =+C13+1 -> 5 | D14: =AND(B14>6,B14<=$B$8) -> TRUE | E14: =IF(D14,$K$4/3*(B14-$B$11),$K$4/3*($B$8-$B$11)+$K$6+$B$9*((B14-$B$8)/B14)) -> 0.15
A15: 6 | B15: =3*A15 -> 18 | C15: =+C14+1 -> 6 | D15: =AND(B15>6,B15<=$B$8) -> TRUE | E15: =IF(D15,$K$4/3*(B15-$B$11),$K$4/3*($B$8-$B$11)+$K$6+$B$9*((B15-$B$8)/B15)) -> 0.2
A16: 7 | B16: =3*A16 -> 21 | C16: =+C15+1 -> 7 | D16: =AND(B16>6,B16<=$B$8) -> TRUE | E16: =IF(D16,$K$4/3*(B16-$B$11),$K$4/3*($B$8-$B$11)+$K$6+$B$9*((B16-$B$8)/B16)) -> 0.25
A17: 8 | B17: =3*A17 -> 24 | C17: =+C16+1 -> 8 | D17: =AND(B17>6,B17<=$B$8) -> TRUE | E17: =IF(D17,$K$4/3*(B17-$B$11),$K$4/3*($B$8-$B$11)+$K$6+$B$9*((B17-$B$8)/B17)) -> 0.3
A18: 9 | B18: =3*A18 -> 27 | C18: =+C17+1 -> 9 | D18: =AND(B18>6,B18<=$B$8) -> TRUE | E18: =IF(D18,$K$4/3*(B18-$B$11),$K$4/3*($B$8-$B$11)+$K$6+$B$9*((B18-$B$8)/B18)) -> 0.35
A19: 10 | B19: =3*A19 -> 30 | C19: =+C18+1 -> 10 | D19: =AND(B19>6,B19<=$B$8) -> TRUE | E19: =IF(D19,$K$4/3*(B19-$B$11),$K$4/3*($B$8-$B$11)+$K$6+$B$9*((B19-$B$8)/B19)) -> 0.4
A20: 11 | B20: =3*A20 -> 33 | C20: =+C19+1 -> 11 | D20: =AND(B20>6,B20<=$B$8) -> TRUE | E20: =IF(D20,$K$4/3*(B20-$B$11),$K$4/3*($B$8-$B$11)+$K$6+$B$9*((B20-$B$8)/B20)) -> 0.45
A21: 12 | B21: =3*A21 -> 36 | C21: =+C20+1 -> 12 | D21: =AND(B21>6,B21<=$B$8) -> TRUE | E21: =IF(D21,$K$4/3*(B21-$B$11),$K$4/3*($B$8-$B$11)+$K$6+$B$9*((B21-$B$8)/B21)) -> 0.5
A22: 13 | B22: =3*A22 -> 39 | C22: =+C21+1 -> 13 | D22: =AND(B22>6,B22<=$B$8) -> TRUE | E22: =IF(D22,$K$4/3*(B22-$B$11),$K$4/3*($B$8-$B$11)+$K$6+$B$9*((B22-$B$8)/B22)) -> 0.55
A23: 14 | B23: =3*A23 -> 42 | C23: =+C22+1 -> 14 | D23: =AND(B23>6,B23<=$B$8) -> TRUE | E23: =IF(D23,$K$4/3*(B23-$B$11),$K$4/3*($B$8-$B$11)+$K$6+$B$9*((B23-$B$8)/B23)) -> 0.6
... A212: 203 | B212: =3*A212 -> 609 | C212: =+C211+1 -> 203 | D212: =AND(B212>6,B212<=$B$8) -> FALSE | E212: =IF(D212,$K$4/3*(B212-$B$11),$K$4/3*($B$8-$B$11)+$K$6+$B$9*((B212-$B$8)/B212)) -> 1.2352217

Sheet Factor2_Elev
C3: Factor 2
I4: pemalidade | J4: 0.1
I5: m | J5: 0.25
A8: Helevador | B8: 15
A10: K | B10: h | C10: Andar | D10: Factor2
A11: 1 | B11: 3 | C11: 1 | D11: 0
A12: 2 | B12: 6 | C12: 2 | D12: 0
A13: 3 | B13: =3*A13 -> 9 | C13: =+C12+1 -> 3 | D13: =IF(B13>$B$8,$J$4+$J$5*(B13-$B$8)/B13,0) -> 0
A14: 4 | B14: =3*A14 -> 12 | C14: =+C13+1 -> 4 | D14: =IF(B14>$B$8,$J$4+$J$5*(B14-$B$8)/B14,0) -> 0
A15: 5 | B15: =3*A15 -> 15 | C15: =+C14+1 -> 5 | D15: =IF(B15>$B$8,$J$4+$J$5*(B15-$B$8)/B15,0) -> 0
A16: 6 | B16: =3*A16 -> 18 | C16: =+C15+1 -> 6 | D16: =IF(B16>$B$8,$J$4+$J$5*(B16-$B$8)/B16,0) -> 0.14166667
A17: 7 | B17: =3*A17 -> 21 | C17: =+C16+1 -> 7 | D17: =IF(B17>$B$8,$J$4+$J$5*(B17-$B$8)/B17,0) -> 0.17142857
A18: 8 | B18: =3*A18 -> 24 | C18: =+C17+1 -> 8 | D18: =IF(B18>$B$8,$J$4+$J$5*(B18-$B$8)/B18,0) -> 0.19375
A19: 9 | B19: =3*A19 -> 27 | C19: =+C18+1 -> 9 | D19: =IF(B19>$B$8,$J$4+$J$5*(B19-$B$8)/B19,0) -> 0.21111111
A20: 10 | B20: =3*A20 -> 30 | C20: =+C19+1 -> 10 | D20: =IF(B20>$B$8,$J$4+$J$5*(B20-$B$8)/B20,0) -> 0.225
A21: 11 | B21: =3*A21 -> 33 | C21: =+C20+1 -> 11 | D21: =IF(B21>$B$8,$J$4+$J$5*(B21-$B$8)/B21,0) -> 0.23636364
A22: 12 | B22: =3*A22 -> 36 | C22: =+C21+1 -> 12 | D22: =IF(B22>$B$8,$J$4+$J$5*(B22-$B$8)/B22,0) -> 0.24583333
A23: 13 | B23: =3*A23 -> 39 | C23: =+C22+1 -> 13 | D23: =IF(B23>$B$8,$J$4+$J$5*(B23-$B$8)/B23,0) -> 0.25384615
A24: 14 | B24: =3*A24 -> 42 | C24: =+C23+1 -> 14 | D24: =IF(B24>$B$8,$J$4+$J$5*(B24-$B$8)/B24,0) -> 0.26071429
... A285: 275 | B285: =3*A285 -> 825 | C285: =+C284+1 -> 275 | D285: =IF(B285>$B$8,$J$4+$J$5*(B285-$B$8)/B285,0) -> 0.34545455

Sheet Factor3_proporção
C5: P1: Zona Histórica | D5: Altura (Andares) | G5: φ3
F6: 0.3
D7: 4 | F7: 0.2 | I7: base | J7: 10 | L7: 20
D8: 3 | F8: 0.1 | I8: altura | J8: 6 | L8: =J8*L7/J7 -> 12 | M8: =L8/3 -> 4 | O8: 6 | Q8: =O8-M8 -> 2
D9: 2 | E9: φ3=0
D10: 1
D12: Altura (Andares)
D13: 10
D14: 9 | F14: 0.4 | G14: φ3 | L14: φ3
C15: P2: Zona Normal | D15: 8 | F15: 0.3 | K15: 0.3
D16: 7 | F16: 0.2 | K16: 0.2
D17: 6 | F17: 0.1 | K17: 0.1
D18: 5 | E18: φ3=0 | G18: φ3=0
D19: 4
D20: 3
D21: 2
D22: 1
F23: 10 | L23: MCB
L24: Menor comprimento da Base
E27: Razão (P1): | F27: 5 | G27: 2 pisos por cada 10m da base | K27: Razão (P2): | L27: 2 | M27: 5 pisos para cada 10 metros da base
E28: Zona Histórica | K28: Zona Normal
E29: Nº Pisos | F29: Fachada (m) | G29: φ3 | K29: Nº Pisos | L29: Fachada (m) | M29: φ3
E30: 0 | F30: 0 | G30: 0 | K30: 0 | L30: 0 | M30: 0
E31: 1 | F31: 5 | G31: 0 | K31: 1 | L31: 2 | M31: 0
E32: 2 | F32: =+F31+$F$27 -> 10 | G32: 0 | K32: 2 | L32: =+L31+$L$27 -> 4 | M32: 0
E33: 3 | F33: =+F32+$F$27 -> 15 | G33: 0.1 | K33: 3 | L33: =+L32+$L$27 -> 6 | M33: 0
E34: 4 | F34: =+F33+$F$27 -> 20 | G34: 0.2 | K34: 4 | L34: =+L33+$L$27 -> 8 | M34: 0
E35: 5 | F35: =+F34+$F$27 -> 25 | G35: 0.3 | K35: 5 | L35: =+L34+$L$27 -> 10 | M35: 0
E36: 6 | F36: =+F35+$F$27 -> 30 | G36: 0.4 | K36: 6 | L36: =+L35+$L$27 -> 12 | M36: 0.1
E37: 7 | F37: =+F36+$F$27 -> 35 | G37: 0.5 | K37: 7 | L37: =+L36+$L$27 -> 14 | M37: 0.2
E38: 8 | F38: =+F37+$F$27 -> 40 | G38: 0.6 | K38: 8 | L38: =+L37+$L$27 -> 16 | M38: 0.3
E39: 9 | F39: =+F38+$F$27 -> 45 | G39: 0.7 | K39: 9 | L39: =+L38+$L$27 -> 18 | M39: 0.4
E40: 10 | F40: =+F39+$F$27 -> 50 | G40: 0.8 | K40: 10 | L40: =+L39+$L$27 -> 20 | M40: 0.5
E41: 11 | F41: =+F40+$F$27 -> 55 | G41: 0.9 | K41: 11 | L41: =+L40+$L$27 -> 22 | M41: 0.6
E42: 12 | F42: =+F41+$F$27 -> 60 | G42: 1 | K42: 12 | L42: =+L41+$L$27 -> 24 | M42: 0.7 | T42: =13.5/3 -> 4.5
E43: 13 | F43: =+F42+$F$27 -> 65 | G43: 1.1 | K43: 13 | L43: =+L42+$L$27 -> 26 | M43: 0.8
E44: 14 | F44: =+F43+$F$27 -> 70 | G44: 1.2 | K44: 14 | L44: =+L43+$L$27 -> 28 | M44: 0.9
E45: 15 | F45: =+F44+$F$27 -> 75 | G45: 1.3 | K45: 15 | L45: =+L44+$L$27 -> 30 | M45: 1
E46: 16 | F46: =+F45+$F$27 -> 80 | G46: 1.4 | K46: 16 | L46: =+L45+$L$27 -> 32 | M46: 1.1
E47: 17 | F47: =+F46+$F$27 -> 85 | G47: 1.5 | K47: 17 | L47: =+L46+$L$27 -> 34 | M47: 1.2
...

Sheet Factor4_Uso
B2: Ponderação e compatibilização na alteração de usos | G2: Uso Alterado
G3: Habitação Unifamiliar | H3: Habitação Multifamiliar | I3: Terciário Pequeno comércio | J3: Terciario Grossista | K3: Terciário Serviços | L3: Misto (Habitação + Terciário/Com-Serv) | M3: Estacionamento | N3: Industria poluente | O3: Industria não poluente | P3: Equipamento | Q3: Turismo | R3: Recreio Urbano (inclui Áreas Verdes) | S3: Recreio Rural | T3: Infra-estruturas (técnicas e públicas) | U3: Agrícola | V3: Florestal | W3: Extração mineira | X3: Pesca
I4: Terciário Pequeno comércio | J4: Terciário Grossista | K4: Terciários Serviços
F5: (sa) | G5: HU | H5: HM | I5: TPC | J5: TG | K5: TS | L5: M | M5: E | N5: IP | O5: INP | P5: EQ | Q5: TUR | R5: RU | S5: RR | T5: IF | U5: AG | V5: FL | W5: EM | X5: PES
B6: Uso Actual | C6: Habitação Unifamiliar | E6: HU | F6: =G6 -> 0 | G6: 0 | H6: 0.1 | I6: 0.1 | J6: 0.2 | K6: 0.1 | L6: 0.15 | M6: 0.05 | N6: 0.2 | O6: 0.1 | P6: 0.05 | Q6: 0.1 | R6: 0.05 | S6: 0.05 | T6: 0.05 | U6: 0.05 | V6: 0.05 | W6: 0.5 | X6: 0.15 | AA6: Uso Actual | AB6: Habitação Unifamiliar | AD6: HU | AE6: =+F6 -> 0 | AH6: 0.05 | AI6: 0.05
C7: Habitação Multifamiliar | E7: HM | F7: =H7 -> 0.05 | G7: 0.15 | H7: 0.05 | I7: =0.1+$H$7 -> 0.15 | J7: =0.15+$H$7 -> 0.2 | K7: =0.05+$H$7 -> 0.1 | L7: =0.05+$H$7 -> 0.1 | M7: 0.05 | N7: 0.5 | O7: 0.15 | P7: 0.05 | Q7: 0.1 | R7: 0.05 | S7: 0.05 | T7: 0.05 | U7: 0.05 | V7: 0.05 | W7: 0.5 | X7: 0.15 | AB7: Habitação Multifamiliar | AC7: Habitação Multifamiliar | AD7: HM | AE7: =+F7 -> 0.05 | AH7: 0.75 | AI7: 0.1
C8: Terciário Pequeno comércio | E8: TPC | F8: =I8 -> 0.05 | G8: 0.1 | H8: 0.1 | I8: 0.05 | J8: 0.2 | K8: 0.1 | L8: 0.1 | M8: 0.05 | N8: 0.5 | O8: 0.1 | P8: 0.05 | Q8: 0.05 | R8: 0.05 | S8: 0.05 | T8: 0.05 | U8: 0.05 | V8: 0.05 | W8: 0.5 | X8: 0.1 | AB8: Terciário Pequeno comércio | AD8: TPC | AE8: =+F8 -> 0.05 | AH8: 1 | AI8: 0.15
C9: Terciario Grossista | E9: TG | F9: =J9 -> 0.1 | G9: 0.05 | H9: 0.05 | I9: 0.05 | J9: 0.1 | K9: 0.15 | L9: 0.15 | M9: 0.05 | N9: 0.5 | O9: 0.2 | P9: 0.05 | Q9: 0.15 | R9: 0.05 | S9: 0.15 | T9: 0.15 | U9: 0.15 | V9: 0.15 | W9: 0.5 | X9: 0.15 | AB9: Terciario Grossista | AD9: TG | AE9: =+F9 -> 0.1 | AH9: 0.25 | AI9: 0.04
C10: Terciário Serviços | E10: TS | F10: =K10 -> 0.05 | G10: 0.1 | H10: 0.1 | I10: 0.1 | J10: 0.15 | K10: 0.05 | L10: 0.1 | M10: 0.05 | N10: 0.5 | O10: 0.15 | P10: 0.05 | Q10: 0.1 | R10: 0.05 | S10: 0.1 | T10: 0.15 | U10: 0.1 | V10: 0.1 | W10: 0.5 | X10: 0.1 | AB10: Terciário Serviços | AD10: TS | AE10: =+F10 -> 0.05 | AH10: 0.1 | AI10: 0.02
C11: Misto (Habitação + Terciário/Com-Serv) | E11: M | F11: =L11 -> 0.1 | G11: 0.15 | H11: 0.15 | I11: 0.15 | J11: 0.2 | K11: 0.15 | L11: 0.1 | M11: 0.05 | N11: 0.5 | O11: 0.2 | P11: 0.05 | Q11: 0.15 | R11: 0.15 | S11: 0.15 | T11: 0.15 | U11: 0.1 | V11: 0.1 | W11: 0.5 | X11: 0.1 | AB11: Misto (Habitação + Terciário/Com-Serv) | AD11: M | AE11: =+F11 -> 0.1
C12: Estacionamento | E12: E | F12: 0.05 | G12: 0.1 | H12: 0.15 | I12: 0.15 | J12: 0.2 | K12: 0.15 | L12: 0.15 | M12: 0.05 | N12: 0.1 | O12: 0.1 | P12: 0.05 | Q12: 0.15 | R12: 0.05 | S12: 0.05 | T12: 0.05 | U12: 0.05 | V12: 0.05 | W12: 0.2 | X12: 0.05 | AB12: Estacionamento | AD12: E | AE12: =+F12 -> 0.05 | AH12: Teste: | AI12: 0.2
C13: Industria poluente | E13: IP | F13: =+N13 -> 0.05 | G13: 0.05 | H13: 0.05 | I13: 0.05 | J13: 0.05 | K13: 0.05 | L13: 0.05 | M13: 0.05 | N13: 0.05 | O13: 0.05 | P13: 0.05 | Q13: 0.05 | R13: 0.05 | S13: 0.05 | T13: 0.05 | U13: 0.1 | V13: 0.05 | W13: 0.2 | X13: 0.05 | AB13: Industria poluente | AD13: IP | AE13: =+F13 -> 0.05 | AH13: 100
C14: Industria não poluente | E14: INP | F14: 0.05 | G14: 0.1 | H14: 0.1 | I14: 0.1 | J14: 0.1 | K14: 0.1 | L14: 0.1 | M14: 0.05 | N14: 0.05 | O14: 0.05 | P14: 0.05 | Q14: 0.05 | R14: 0.05 | S14: 0.05 | T14: 0.05 | U14: 0.05 | V14: 0.05 | W14: 0.2 | X14: 0.1 | AB14: Industria não poluente | AD14: INP | AE14: =+F14 -> 0.05 | AH14: 4000 | AI14: =AH14*AI12 -> 800 | AJ14: =AH14+AI14 -> 4800
C15: Equipamento | E15: EQ | F15: 0.05 | G15: 0.1 | H15: 0.15 | I15: 0.1 | J15: 0.15 | K15: 0.1 | L15: 0.15 | M15: 0.05 | N15: 0.5 | O15: 0.15 | P15: 0.05 | Q15: 0.15 | R15: 0.05 | S15: 0.05 | T15: 0.05 | U15: 0.05 | V15: 0.05 | W15: 0.5 | X15: 0.05 | AB15: Equipamento | AD15: EQ | AE15: =+F15 -> 0.05 | AH15: =AH14*AH13 -> 400000 | AI15: =AH15*AI12 -> 80000 | AJ15: =AH15+AI15 -> 480000
C16: Turismo | E16: TUR | F16: =+Q16 -> 0.1 | G16: 0.05 | H16: 0.05 | I16: 0.1 | J16: 0.15 | K16: 0.15 | L16: 0.15 | M16: 0.05 | N16: 0.5 | O16: 0.15 | P16: 0.05 | Q16: 0.1 | R16: 0.05 | S16: 0.05 | T16: 0.05 | U16: 0.05 | V16: 0.05 | W16: 0.5 | X16: 0.1 | AB16: Turismo | AD16: TUR | AE16: =+F16 -> 0.1
C17: Recreio Urbano (inclui Áreas Verdes) | E17: RU | F17: 0.05 | G17: 0.1 | H17: 0.15 | I17: 0.1 | J17: 0.15 | K17: 0.1 | L17: 0.15 | M17: 0.05 | N17: 0.5 | O17: 0.1 | P17: 0.05 | Q17: 0.05 | R17: 0.05 | S17: 0.05 | T17: 0.05 | U17: 0.05 | V17: 0.05 | W17: 0.5 | X17: 0.05 | AB17: Recreio Urbano (inclui Áreas Verdes) | AD17: RU | AE17: =+F17 -> 0.05 | AG17: 1 | AH17: facilitado/incentivado | AL17: 0
C18: Recreio Rural | E18: RR | F18: 0.05 | G18: 0.05 | H18: 0.15 | I18: 0.1 | J18: 0.15 | K18: 0.1 | L18: 0.2 | M18: 0.05 | N18: 0.2 | O18: 0.1 | P18: 0.05 | Q18: 0.05 | R18: 0.05 | S18: 0.05 | T18: 0.05 | U18: 0.05 | V18: 0.05 | W18: 0.2 | X18: 0.05 | AB18: Recreio Rural | AD18: RR | AE18: =+F18 -> 0.05 | AG18: 2 | AH18: compatível | AL18: 0.05
C19: Infra-estruturas (técnicas e públicas) | E19: IF | F19: 0.05 | G19: 0.1 | H19: 0.15 | I19: 0.1 | J19: 0.15 | K19: 0.1 | L19: 0.15 | M19: 0.05 | N19: 0.15 | O19: 0.05 | P19: 0.05 | Q19: 0.05 | R19: 0.05 | S19: 0.05 | T19: 0.05 | U19: 0.05 | V19: 0.05 | W19: 0.15 | X19: 0.05 | AB19: Infra-estruturas (técnicas e públicas) | AD19: IF | AE19: =+F19 -> 0.05 | AG19: 3 | AH19: compatível/tolerância média | AL19: 0.1
C20: Agrícola | E20: AG | F20: 0.05 | G20: 0.05 | H20: 0.5 | I20: 0.05 | J20: 0.1 | K20: 0.05 | L20: 0.5 | M20: 0.2 | N20: 0.5 | O20: 0.1 | P20: 0.05 | Q20: 0.05 | R20: 0.05 | S20: 0.05 | T20: 0.1 | U20: 0.05 | V20: 0.05 | W20: 0.5 | X20: 0.05 | AB20: Agrícola | AD20: AG | AE20: =+F20 -> 0.05 | AG20: 4 | AH20: compatível/tolerância mais restritiva | AL20: 0.15
C21: Florestal | E21: FL | F21: 0.05 | G21: 0.05 | H21: 0.2 | I21: 0.05 | J21: 0.05 | K21: 0.05 | L21: 0.2 | M21: 0.2 | N21: 0.15 | O21: 0.1 | P21: 0.05 | Q21: 0.05 | R21: 0.05 | S21: 0.05 | T21: 0.1 | U21: 0.05 | V21: 0.05 | W21: 0.2 | X21: 0.05 | AB21: Florestal | AD21: FL | AE21: =+F21 -> 0.05 | AG21: 5 | AH21: incompatível | AL21: 0.2
C22: Extração mineira | E22: EM | F22: 0.05 | G22: 0.15 | H22: 0.15 | I22: 0.1 | J22: 0.1 | K22: 0.1 | L22: 0.15 | M22: 0.05 | N22: 0.05 | O22: 0.05 | P22: 0.05 | Q22: 0.05 | R22: 0.05 | S22: 0.05 | T22: 0.05 | U22: 0.05 | V22: 0.05 | W22: 0.05 | X22: 0.15 | AB22: Extração mineira | AD22: EM | AE22: =+F22 -> 0.05 | AG22: 6 | AH22: penalização máxima | AL22: 0.5
C23: Pesca | E23: PES | F23: 0.05 | G23: 0.05 | H23: 0.1 | I23: 0.05 | J23: 0.05 | K23: 0.05 | L23: 0.1 | M23: 0.05 | N23: 0.2 | O23: 0.05 | P23: 0.05 | Q23: 0.05 | R23: 0.05 | S23: 0.05 | T23: 0.05 | U23: 0.05 | V23: 0.05 | W23: 0.2 | X23: 0.05 | AB23: Pesca | AD23: PES | AE23: =+F23 -> 0.05
C26: ponderação mínima Tabela Mudança de Uso: 0,05
C27: (Preço ref. Bairro*0,05*Área)

Sheet N_Vistas
B2: Nº Vistas | C2: Valor
B3: 1 | C3: 0
B4: 2 | C4: 0.05
B5: 3 | C5: 0.075
B6: 4 | C6: 0.1

Sheet Factor5_infra
B6: Fi MAX | C6: 0.2
B7: L | C7: φ5
B8: 10 | C8: 0
B9: =+B8+1 -> 11 | C9: =+$C$6*(B9-$B$8)/B9 -> 0.018181818
B10: =+B9+1 -> 12 | C10: =+$C$6*(B10-$B$8)/B10 -> 0.033333333
B11: =+B10+1 -> 13 | C11: =+$C$6*(B11-$B$8)/B11 -> 0.046153846
B12: =+B11+1 -> 14 | C12: =+$C$6*(B12-$B$8)/B12 -> 0.057142857
B13: =+B12+1 -> 15 | C13: =+$C$6*(B13-$B$8)/B13 -> 0.066666667
B14: =+B13+1 -> 16 | C14: =+$C$6*(B14-$B$8)/B14 -> 0.075
B15: =+B14+1 -> 17 | C15: =+$C$6*(B15-$B$8)/B15 -> 0.082352941
B16: =+B15+1 -> 18 | C16: =+$C$6*(B16-$B$8)/B16 -> 0.088888889
B17: =+B16+1 -> 19 | C17: =+$C$6*(B17-$B$8)/B17 -> 0.094736842
B18: =+B17+1 -> 20 | C18: =+$C$6*(B18-$B$8)/B18 -> 0.1
B19: =+B18+1 -> 21 | C19: =+$C$6*(B19-$B$8)/B19 -> 0.1047619
B20: =+B19+1 -> 22 | C20: =+$C$6*(B20-$B$8)/B20 -> 0.10909091
... B548: =+B547+1 -> 550 | C548: =+$C$6*(B548-$B$8)/B548 -> 0.19636364

Sheet PREÇO BAIRROS
Q2: PARÂMETRO VALORIZAÇÃO DO BAIRRO | R2: PREÇO BASE DE REFERÊNCIA/m2 TERRENO (normal e social)
E3: Preço esc/m2 (Ponderação) | R3: 2000 | T3: PREÇO SOCAIL
A4: Código Bairro | B4: zona | C4: Nome Bairro | D4: Categoria | E4: Alta | F4: Média | G4: Baixa | H4: Código Bairro | I4: Zona Histórica | J4: Área (m2) | K4: População Estimada | L4: Pop INE 2010 | M4: Área (km2) | N4: Pop/km2 | O4: Pop/km2 (INE) | Q4: Categoria | R4: Ponderação | S4: Preço Normal/m2 | T4: Ponderação | U4: Preço Social/m2
A5: 0101 | B5: Praia Norte | C5: Paiol | D5: III | E5: 3500 | F5: 2100 | G5: 1500 | H5: 0101 | I5: Não | J5: 81349 | K5: 1447.7328 | L5: 1265 | M5: =J5/1000000 -> 0.081349 | N5: =K5/M5 -> 17796.566 | O5: =L5/M5 -> 15550.283 | Q5: III | S5: =VLOOKUP(Q5,$X$13:$AA$17,3,0) -> 3500 | U5: =VLOOKUP(Q5,$X$13:$AA$17,4,0) -> 1750
A6: 0102 | B6: Praia Norte | C6: Lem Cachorro | D6: III | E6: 3500 | F6: 2100 | G6: 1500 | H6: 0102 | I6: Não | J6: 110272 | K6: 2122.6894 | L6: 2291 | M6: =J6/1000000 -> 0.110272 | N6: =K6/M6 -> 19249.577 | O6: =L6/M6 -> 20775.9 | Q6: III | S6: =VLOOKUP(Q6,$X$13:$AA$17,3,0) -> 3500 | U6: =VLOOKUP(Q6,$X$13:$AA$17,4,0) -> 1750
A7: 0103 | B7: Praia Norte | C7: Achadinha Pires | D7: III | E7: 3500 | F7: 2100 | G7: 1500 | H7: 0103 | I7: Não | J7: 92647 | K7: 912.98467 | L7: 1015 | M7: =J7/1000000 -> 0.092647 | N7: =K7/M7 -> 9854.444 | O7: =L7/M7 -> 10955.563 | Q7: III | S7: =VLOOKUP(Q7,$X$13:$AA$17,3,0) -> 3500 | U7: =VLOOKUP(Q7,$X$13:$AA$17,4,0) -> 1750
A8: 0104 | B8: Praia Norte | C8: Coqueiro Castelão | D8: III | E8: 3500 | F8: 2100 | G8: 1500 | H8: 0104 | I8: Não | J8: 417728 | K8: 4101.9097 | L8: 4613 | M8: =J8/1000000 -> 0.417728 | N8: =K8/M8 -> 9819.5709 | O8: =L8/M8 -> 11043.071 | Q8: III | S8: =VLOOKUP(Q8,$X$13:$AA$17,3,0) -> 3500 | U8: =VLOOKUP(Q8,$X$13:$AA$17,4,0) -> 1750
A9: 0105 | B9: Praia Norte | C9: Achada Mato | D9: III | E9: 3500 | F9: 2100 | G9: 1500 | H9: 0105 | I9: Não | J9: 481719 | K9: 1871.6186 | L9: 2001 | M9: =J9/1000000 -> 0.481719 | N9: =K9/M9 -> 3885.2912 | O9: =L9/M9 -> 4153.8739 | Q9: III | S9: =VLOOKUP(Q9,$X$13:$AA$17,3,0) -> 3500 | U9: =VLOOKUP(Q9,$X$13:$AA$17,4,0) -> 1750
A10: 0106 | B10: Praia Norte | C10: Agua Funda | D10: IV | E10: 3000 | F10: 1500 | G10: 1200 | H10: 0106 | I10: Não | J10: 927402 | K10: 818.42554 | L10: 760 | M10: =J10/1000000 -> 0.927402 | N10: =K10/M10 -> 882.49275 | O10: =L10/M10 -> 819.4936 | Q10: IV | S10: =VLOOKUP(Q10,$X$13:$AA$17,3,0) -> 1500 | U10: =VLOOKUP(Q10,$X$13:$AA$17,4,0) -> 1000
A11: 0107 | B11: Praia Norte | C11: Achada Limpo | D11: III | E11: 3500 | F11: 2100 | G11: 1500 | H11: 0107 | I11: Não | J11: 1822544 | K11: 32.606595 | L11: 16 | M11: =J11/1000000 -> 1.822544 | N11: =K11/M11 -> 17.890704 | O11: =L11/M11 -> 8.7789376 | Q11: III | S11: =VLOOKUP(Q11,$X$13:$AA$17,3,0) -> 3500 | U11: =VLOOKUP(Q11,$X$13:$AA$17,4,0) -> 1750
A12: 0108 | B12: Praia Norte | C12: Ribeira S. Filipe | D12: IV | E12: 3000 | F12: 1500 | G12: 1200 | H12: 0108 | I12: Não | J12: 1197631 | K12: 264.11342 | L12: 248 | M12: =J12/1000000 -> 1.197631 | N12: =K12/M12 -> 220.52988 | O12: =L12/M12 -> 207.07547 | Q12: IV | S12: =VLOOKUP(Q12,$X$13:$AA$17,3,0) -> 1500 | U12: =VLOOKUP(Q12,$X$13:$AA$17,4,0) -> 1000 | X12: PARÂMETRO VALORIZAÇÃO DE BAIRROS | Z12: Normal | AA12: Social
A13: 0109 | B13: Praia Norte | C13: Ponta de Agua | D13: III | E13: 3500 | F13: 2100 | G13: 1500 | H13: 0109 | I13: Não | J13: 614639 | K13: 8683.1363 | L13: 8682 | M13: =J13/1000000 -> 0.614639 | N13: =K13/M13 -> 14127.213 | O13: =L13/M13 -> 14125.365 | Q13: III | S13: =VLOOKUP(Q13,$X$13:$AA$17,3,0) -> 3500 | U13: =VLOOKUP(Q13,$X$13:$AA$17,4,0) -> 1750 | X13: I | Y13: Valorização máxima (ex: Plateau) | Z13: 8000 | AA13: 4000 | AB13: =AA13/Z13 -> 0.5
A14: 0110 | B14: Praia Norte | C14: Vila Nova | D14: III | E14: 3500 | F14: 2100 | G14: 1500 | H14: 0110 | I14: Não | J14: 231171 | K14: 4454.0609 | L14: 4868 | M14: =J14/1000000 -> 0.231171 | N14: =K14/M14 -> 19267.386 | O14: =L14/M14 -> 21058.005 | Q14: III | S14: =VLOOKUP(Q14,$X$13:$AA$17,3,0) -> 3500 | U14: =VLOOKUP(Q14,$X$13:$AA$17,4,0) -> 1750 | X14: II | Y14: Valorização média/alta (ex: ASA) | Z14: 6000 | AA14: 3000 | AB14: =AA14/Z14 -> 0.5
A15: 0111 | B15: Praia Norte | C15: Safende | D15: IV | E15: 3000 | F15: 1500 | G15: 1200 | H15: 0111 | I15: Não | J15: 616972 | K15: 5601.8131 | L15: 6151 | M15: =J15/1000000 -> 0.616972 | N15: =K15/M15 -> 9079.5256 | O15: =L15/M15 -> 9969.6583 | Q15: IV | S15: =VLOOKUP(Q15,$X$13:$AA$17,3,0) -> 1500 | U15: =VLOOKUP(Q15,$X$13:$AA$17,4,0) -> 1000 | X15: III | Y15: Valorização média/baixa (ex: Achadinha) | Z15: 3500 | AA15: 1750 | AB15: =AA15/Z15 -> 0.5
A16: 0112 | B16: Praia Norte | C16: Calabaceira | D16: III | E16: 3500 | F16: 2100 | G16: 1500 | H16: 0112 | I16: Não | J16: 282678 | K16: 4698.6104 | L16: 4582 | M16: =J16/1000000 -> 0.282678 | N16: =K16/M16 -> 16621.776 | O16: =L16/M16 -> 16209.256 | Q16: III | S16: =VLOOKUP(Q16,$X$13:$AA$17,3,0) -> 3500 | U16: =VLOOKUP(Q16,$X$13:$AA$17,4,0) -> 1750 | X16: IV | Y16: Valorização baixa (ex: alguns bairros AUGI) | Z16: 1500 | AA16: 1000 | AB16: =AA16/Z16 -> 0.66666667
A17: 0113 | B17: Praia Norte | C17: S. Pedro Latada | D17: IV | E17: 3000 | F17: 1500 | G17: 1200 | H17: 0113 | I17: Não | J17: 496516 | K17: 2820.4705 | L17: 2627 | M17: =J17/1000000 -> 0.496516 | N17: =K17/M17 -> 5680.5229 | O17: =L17/M17 -> 5290.8668 | Q17: IV | S17: =VLOOKUP(Q17,$X$13:$AA$17,3,0) -> 1500 | U17: =VLOOKUP(Q17,$X$13:$AA$17,4,0) -> 1000 | X17: V | Y17: Valorização zonas rurais (ex: propriedade rústica) | Z17: 1000 | AA17: 800 | AB17: =AA17/Z17 -> 0.8
A18: 0114 | B18: Praia Norte | C18: Monte Gonçalo Afonso | D18: IV | E18: 3000 | F18: 1500 | G18: 1200 | H18: 0114 | I18: Não | J18: 888533 | K18: 1340.1311 | L18: 1104 | M18: =J18/1000000 -> 0.888533 | N18: =K18/M18 -> 1508.2513 | O18: =L18/M18 -> 1242.4975 | Q18: IV | S18: =VLOOKUP(Q18,$X$13:$AA$17,3,0) -> 1500 | U18: =VLOOKUP(Q18,$X$13:$AA$17,4,0) -> 1000
A19: 0115 | B19: Praia Norte | C19: Gonçalo Afonso | D19: IV | E19: 3000 | F19: 1500 | G19: 1200 | H19: 0115 | I19: Não | J19: 1284710 | K19: 192.37891 | L19: 111 | M19: =J19/1000000 -> 1.28471 | N19: =K19/M19 -> 149.74501 | O19: =L19/M19 -> 86.400822 | Q19: IV | S19: =VLOOKUP(Q19,$X$13:$AA$17,3,0) -> 1500 | U19: =VLOOKUP(Q19,$X$13:$AA$17,4,0) -> 1000
A20: 0116 | B20: Praia Norte | C20: Monteagarro | D20: III | E20: 3500 | F20: 2100 | G20: 1500 | H20: 0116 | I20: Não | J20: 259095 | K20: 1695.543 | L20: 1607 | M20: =J20/1000000 -> 0.259095 | N20: =K20/M20 -> 6544.0976 | O20: =L20/M20 -> 6202.3582 | Q20: III | S20: =VLOOKUP(Q20,$X$13:$AA$17,3,0) -> 3500 | U20: =VLOOKUP(Q20,$X$13:$AA$17,4,0) -> 1750
A21: 0117 | B21: Praia Norte | C21: Achada S. Filipe | D21: III | E21: 3500 | F21: 2100 | G21: 1500 | H21: 0117 | I21: Não | J21: 3080466 | K21: 6589.7929 | L21: 5734 | M21: =J21/1000000 -> 3.080466 | N21: =K21/M21 -> 2139.2195 | O21: =L21/M21 -> 1861.4067 | Q21: II | S21: =VLOOKUP(Q21,$X$13:$AA$17,3,0) -> 6000 | U21: =VLOOKUP(Q21,$X$13:$AA$17,4,0) -> 3000
A22: 0201 | B22: Praia Centro | C22: Plateau | D22: I | E22: 8000 | F22: 6000 | G22: 4500 | H22: 0201 | I22: Sim | J22: 296977 | K22: 2259.6371 | L22: 1019 | M22: =J22/1000000 -> 0.296977 | N22: =K22/M22 -> 7608.7948 | O22: =L22/M22 -> 3431.2422 | Q22: I | S22: =VLOOKUP(Q22,$X$13:$AA$17,3,0) -> 8000 | U22: =VLOOKUP(Q22,$X$13:$AA$17,4,0) -> 4000
A23: 0202 | B23: Praia Centro | C23: Praia Negra | D23: II | E23: 6000 | F23: 4500 | G23: 3500 | H23: 0202 | I23: Não | J23: 156169 | K23: 45.649233 | L23: 31 | M23: =J23/1000000 -> 0.156169 | N23: =K23/M23 -> 292.30663 | O23: =L23/M23 -> 198.5029 | Q23: II | S23: =VLOOKUP(Q23,$X$13:$AA$17,3,0) -> 6000 | U23: =VLOOKUP(Q23,$X$13:$AA$17,4,0) -> 3000
A24: 0203 | B24: Praia Centro | C24: Fazenda Sucupira | D24: II | E24: 6000 | F24: 4500 | G24: 3500 | H24: 0203 | I24: Não | J24: 259483 | K24: 2836.7738 | L24: 1848 | M24: =J24/1000000 -> 0.259483 | N24: =K24/M24 -> 10932.407 | O24: =L24/M24 -> 7121.8538 | Q24: II | S24: =VLOOKUP(Q24,$X$13:$AA$17,3,0) -> 6000 | U24: =VLOOKUP(Q24,$X$13:$AA$17,4,0) -> 3000
A25: 0204 | B25: Praia Centro | C25: Tahiti Chã de Areia | D25: II | E25: 6000 | F25: 4500 | G25: 3500 | H25: 0204 | I25: Não | J25: 254925 | K25: 378.23651 | L25: 117 | M25: =J25/1000000 -> 0.254925 | N25: =K25/M25 -> 1483.7168 | O25: =L25/M25 -> 458.95852 | Q25: II | S25: =VLOOKUP(Q25,$X$13:$AA$17,3,0) -> 6000 | U25: =VLOOKUP(Q25,$X$13:$AA$17,4,0) -> 3000
A26: 0205 | B26: Praia Centro | C26: Gamboa | D26: I | E26: 8000 | F26: 6000 | G26: 4500 | H26: 0205 | I26: Não | J26: 114016 | K26: 16.303298 | L26: 0 | M26: =J26/1000000 -> 0.114016 | N26: =K26/M26 -> 142.99131 | O26: =L26/M26 -> 0 | Q26: II | S26: =VLOOKUP(Q26,$X$13:$AA$17,3,0) -> 6000 | U26: =VLOOKUP(Q26,$X$13:$AA$17,4,0) -> 3000
A27: 0206 | B27: Praia Centro | C27: Ilheu de Santa Maria | D27: I | E27: 8000 | F27: 6000 | G27: 4500 | H27: 0206 | I27: Não | J27: 60212 | K27: 0 | L27: 0 | M27: =J27/1000000 -> 0.060212 | N27: =K27/M27 -> 0 | O27: =L27/M27 -> 0 | Q27: II | S27: =VLOOKUP(Q27,$X$13:$AA$17,3,0) -> 6000 | U27: =VLOOKUP(Q27,$X$13:$AA$17,4,0) -> 3000
A28: 0301 | B28: Praia Sul | C28: Achada S. Antonio | D28: II | E28: 6000 | F28: 4500 | G28: 3500 | H28: 0301 | I28: Não | J28: 887145 | K28: 11397.868 | L28: 12965 | M28: =J28/1000000 -> 0.887145 | N28: =K28/M28 -> 12847.808 | O28: =L28/M28 -> 14614.296 | Q28: II | S28: =VLOOKUP(Q28,$X$13:$AA$17,3,0) -> 6000 | U28: =VLOOKUP(Q28,$X$13:$AA$17,4,0) -> 3000
A29: 0302 | B29: Praia Sul | C29: Chã de Areia Encosta ASA | D29: II | E29: 6000 | F29: 4500 | G29: 3500 | H29: 0302 | I29: Não | J29: 75280 | K29: 221.72485 | L29: 130 | M29: =J29/1000000 -> 0.07528 | N29: =K29/M29 -> 2945.3354 | O29: =L29/M29 -> 1726.8863 | Q29: III | S29: =VLOOKUP(Q29,$X$13:$AA$17,3,0) -> 3500 | U29: =VLOOKUP(Q29,$X$13:$AA$17,4,0) -> 1750
... A92: 0808 | B92: Praia Sudoeste | C92: Matão | D92: V | E92: 1500 | F92: 1000 | G92: 800 | H92: 0808 | I92: Não | J92: 1202732 | K92: 198.90023 | L92: 171 | M92: =J92/1000000 -> 1.202732 | N92: =K92/M92 -> 165.37369 | O92: =L92/M92 -> 142.17631 | Q92: V | S92: =VLOOKUP(Q92,$X$13:$AA$17,3,0) -> 1000 | U92: =VLOOKUP(Q92,$X$13:$AA$17,4,0) -> 800

Sheet Folha1
C1: PARÂMETRO VALORIZAÇÃO DO BAIRRO | D1: PREÇO BASE DE REFERÊNCIA esc/m2 TERRENO
A2: PRAIA NORTE (U1/01)
A3: Cod. | B3: Nome Bairro/Localidade | C3: Categoria | D3: Preço esc/m2 (Ponderação) | I3: Cod. | J3: Nome Bairro/Localidade | K3: Categoria | L3: Preço esc/m2 (Ponderação)
D4: a) Alta | E4: b) Média | F4: c) Baixa | L4: a) Alta | M4: b) Média | N4: c) Baixa
A5: 101 | B5: Paiol | C5: III | D5: 3500 | E5: 2100 | F5: 1500 | I5: 101 | J5: Paiol | K5: III | L5: 3500 | M5: 2100 | N5: 1500
A6: 102 | B6: Lem Cachorro | C6: III | D6: 3500 | E6: 2100 | F6: 1500 | I6: 102 | J6: Lem Cachorro | K6: III | L6: 3500 | M6: 2100 | N6: 1500
A7: 103 | B7: Achadinha Pires | C7: III | D7: 3500 | E7: 2100 | F7: 1500 | I7: 103 | J7: Achadinha Pires | K7: III | L7: 3500 | M7: 2100 | N7: 1500
A8: 104 | B8: Coqueiro Castelão | C8: III | D8: 3500 | E8: 2100 | F8: 1500 | I8: 104 | J8: Coqueiro Castelão | K8: III | L8: 3500 | M8: 2100 | N8: 1500
A9: 105 | B9: Achada Mato | C9: III | D9: 3500 | E9: 2100 | F9: 1500 | I9: 105 | J9: Achada Mato | K9: III | L9: 3500 | M9: 2100 | N9: 1500
A10: 106 | B10: Agua Funda | C10: IV | D10: 3000 | E10: 1500 | F10: 1200 | I10: 106 | J10: Agua Funda | K10: IV | L10: 3000 | M10: 1500 | N10: 1200
A11: 107 | B11: Achada Limpo | C11: III | D11: 3500 | E11: 2100 | F11: 1500 | I11: 107 | J11: Achada Limpo | K11: III | L11: 3500 | M11: 2100 | N11: 1500
A12: 108 | B12: Ribeira São Filipe | C12: IV | D12: 3000 | E12: 1500 | F12: 1200 | I12: 108 | J12: Ribeira São Filipe | K12: IV | L12: 3000 | M12: 1500 | N12: 1200
A13: 109 | B13: Ponta de Agua | C13: III | D13: 3500 | E13: 2100 | F13: 1500 | I13: 109 | J13: Ponta de Agua | K13: III | L13: 3500 | M13: 2100 | N13: 1500
A14: 110 | B14: Vila Nova | C14: III | D14: 3500 | E14: 2100 | F14: 1500 | I14: 110 | J14: Vila Nova | K14: III | L14: 3500 | M14: 2100 | N14: 1500
A15: 111 | B15: Safende | C15: IV | D15: 3000 | E15: 1500 | F15: 1200 | I15: 111 | J15: Safende | K15: IV | L15: 3000 | M15: 1500 | N15: 1200
A16: 112 | B16: Calabaceira | C16: III | D16: 3500 | E16: 2100 | F16: 1500 | I16: 112 | J16: Calabaceira | K16: III | L16: 3500 | M16: 2100 | N16: 1500
... A21: 117 | B21: Achada São Filipe | C21: III | D21: 3500 | E21: 2100 | F21: 1500 | I21: 117 | J21: Achada São Filipe | K21: III | L21: 3500 | M21: 2100 | N21: 1500
I22: 201 | J22: Plateau | K22: I | L22: 8000 | M22: 6000 | N22: 4500
C23: PARÂMETRO VALORIZAÇÃO DO BAIRRO | D23: PREÇO BASE DE REFERÊNCIA esc/m2 TERRENO | I23: 202 | J23: Praia Negra | K23: II | L23: 6000 | M23: 4500 | N23: 3500
A24: PRAIA CENTRO (U2/02) | I24: 203 | J24: Fazenda Sucupira | K24: II | L24: 6000 | M24: 4500 | N24: 3500
A25: Cod. | B25: Nome Bairro/Localidade | C25: Categoria | D25: Preço esc/m2 (Ponderação) | I25: 204 | J25: Tahiti Chã de Areia | K25: II | L25: 6000 | M25: 4500 | N25: 3500
D26: a) Alta | E26: b) Média | F26: c) Baixa | I26: 205 | J26: Gamboa | K26: I | L26: 8000 | M26: 6000 | N26: 4500
A27: 201 | B27: Plateau | C27: I | D27: 8000 | E27: 6000 | F27: 4500 | I27: 206 | J27: Ilheu de Santa Maria | K27: I | L27: 8000 | M27: 6000 | N27: 4500
A28: 202 | B28: Praia Negra | C28: II | D28: 6000 | E28: 4500 | F28: 3500 | I28: 301 | J28: Achada S. Antonio | K28: II | L28: 6000 | M28: 4500 | N28: 3500
A29: 203 | B29: Fazenda Sucupira | C29: II | D29: 6000 | E29: 4500 | F29: 3500 | I29: 302 | J29: Chã de Areia | K29: II | L29: 6000 | M29: 4500 | N29: 3500
A30: 204 | B30: Tahiti Chã de Areia | C30: II | D30: 6000 | E30: 4500 | F30: 3500 | I30: 303 | J30: Prainha | K30: I | L30: 8000 | M30: 6000 | N30: 4500
A31: 205 | B31: Gamboa | C31: I | D31: 8000 | E31: 6000 | F31: 4500 | I31: 304 | J31: Quebra Canela | K31: I | L31: 8000 | M31: 6000 | N31: 4500
A32: 206 | B32: Ilheu de Santa Maria | C32: I | D32: 8000 | E32: 6000 | F32: 4500 | I32: 305 | J32: Vale Palmarejo | K32: IV | L32: 3000 | M32: 1500 | N32: 1200
I33: 306 | J33: Tira Chapeu | K33: III | L33: 3500 | M33: 2100 | N33: 1500
C34: PARÂMETRO VALORIZAÇÃO DO BAIRRO | D34: PREÇO BASE DE REFERÊNCIA esc/m2 TERRENO | I34: 307 | J34: Palmarejo | K34: II | L34: 6000 | M34: 4500 | N34: 3500
A35: PRAIA SUL (U3/03) | I35: 308 | J35: Monte Vermelho | K35: III | L35: 3500 | M35: 2100 | N35: 1500
A36: Cod. | B36: Nome Bairro/Localidade | C36: Categoria | D36: Preço esc/m2 (Ponderação) | I36: 309 | J36: Cidadela Cova Minhoto | K36: II | L36: 6000 | M36: 4500 | N36: 3500
D37: a) Alta | E37: b) Média | F37: c) Baixa | I37: 310 | J37: Palmarejo Grande | K37: II | L37: 6000 | M37: 4500 | N37: 3500
A38: 301 | B38: Achada S. Antonio | C38: II | D38: 6000 | E38: 4500 | F38: 3500 | I38: 401 | J38: Achada Grande Frente | K38: III | L38: 3500 | M38: 2100 | N38: 1500
A39: 302 | B39: Chã de Areia | C39: II | D39: 6000 | E39: 4500 | F39: 3500 | I39: 402 | J39: Lem Ferreira | K39: III | L39: 3500 | M39: 2100 | N39: 1500
A40: 303 | B40: Prainha | C40: I | D40: 8000 | E40: 6000 | F40: 4500 | I40: 403 | J40: Zona do Porto da Praia | K40: II | L40: 6000 | M40: 4500 | N40: 3500
A41: 304 | B41: Quebra Canela | C41: I | D41: 8000 | E41: 6000 | F41: 4500 | I41: 404 | J41: Achada Grande Tras | K41: III | L41: 3500 | M41: 2100 | N41: 1500
A42: 305 | B42: Vale Palmarejo | C42: IV | D42: 3000 | E42: 1500 | F42: 1200 | I42: 405 | J42: Ponta Bicuda | K42: II | L42: 6000 | M42: 4500 | N42: 3500
A43: 306 | B43: Tira Chapeu | C43: III | D43: 3500 | E43: 2100 | F43: 1500 | I43: 406 | J43: Zona do Aeroporto | K43: II | L43: 6000 | M43: 4500 | N43: 3500
A44: 307 | B44: Palmarejo | C44: II | D44: 6000 | E44: 4500 | F44: 3500 | I44: 407 | J44: Monte Facho | K44: III | L44: 3500 | M44: 2100 | N44: 1500
...
